Workbook

Sheet Outubro
G2: Outubro
B7: ENTRADAS | G7: GASTOS FIXOS | M7: GASTOS VARIÁVEIS | T7: COFRINHOS
B8: Data | C8: Descrição | D8: Valor | E8: Forma | G8: Data | H8: Descrição | I8: Categoria | J8: Valor | K8: Forma | M8: Data | N8: Descrição | O8: Categoria | P8: Parcelas | Q8: Valor | R8: Forma | T8: Data | U8: Categoria | V8: Valor | W8: Rendimentos | X8: Prazo | Y8: Progreso | Z8: Meta
B9: 07/10 | C9: Reembolsos | D9: 88 | E9: Itaú | G9: 45919 | H9: WeMeds | I9: Educação médica | J9: 34.99 | K9: Itaú | M9: 45751 | N9: Tênis André | O9: Reembolsos | P9: 45907 | Q9: 99.99 | R9: Nubank | T9: 45947 | U9: Reserva | V9: 10000 | X9: - | Y9: =(V9:V97/Z9:Z97) -> 0.4 | Z9: 25000
B10: 13/10 | C10: Reembolsos | D10: 104.9 | E10: Itaú | G10: 45925 | H10: Ta de Clinicagem | I10: Educação médica | J10: 34.9 | K10: Itaú | M10: 45804 | N10: Apice Comesticos | O10: Bem-estar/Saúde | P10: 45782 | Q10: 46.78 | R10: Nubank | T10: 45950 | U10: Residência | V10: 3200 | X10: 46447 | Y10: =(V9:V97/Z9:Z97) -> 0.064 | Z10: 50000
B11: 13/10 | C11: Aval | D11: 640 | E11: Itaú | G11: 45926 | H11: Vivo Celular | I11: Celular/tecnologia | J11: 85 | K11: Itaú | M11: 45857 | N11: Araújo | O11: Bem-estar/Saúde | P11: 45719 | Q11: 95.08 | R11: Itaú | T11: 45950 | U11: Móveis | V11: 1000 | X11: 46023 | Y11: =(V9:V97/Z9:Z97) -> 0.15384615 | Z11: 6500
B12: 14/10 | C12: Asmel | D12: 1988 | E12: Itaú | G12: 45936 | H12: Spotify | I12: Lazer | J12: 15.95 | K12: Pix | M12: 45891 | N12: Autoescola | O12: Educação médica | P12: 45718 | Q12: 390.22 | R12: Itaú | T12: 45950 | U12: Viagem | V12: 1000 | X12: 45992 | Y12: =(V9:V97/Z9:Z97) -> 0.2 | Z12: 5000
B13: 14/10 | C13: Salubritá | D13: 3199.11 | E13: Nubank | G13: 45937 | H13: Contabilidade | I13: Contabilidade/impostos | J13: 282.4 | K13: Boleto | M13: 45894 | N13: Presente Bee | O13: Presentes | P13: 45690 | Q13: 54.75 | R13: Itaú | U13: Total | V13: =SUM(V9:V12) -> 15200 | Y13: =(V9:V97/Z9:Z97) -> 0.17572254 | Z13: =SUM(Z9:Z12) -> 86500
B14: 17/10 | C14: Reembolsos | D14: 79.72 | E14: Itaú | G14: 45938 | H14: Manicure | I14: Beleza | J14: 148.92 | K14: Itaú | M14: 45905 | N14: Tênis Andrê | O14: Reembolsos | P14: 45902 | Q14: 100.07 | R14: Itaú
B15: 20/10 | C15: Reembolsos | D15: 60 | E15: Itaú | G15: 45942 | H15: Whitebook | I15: Educação médica | J15: 69.9 | K15: Itaú | M15: 45905 | N15: Marisa | O15: Roupas/acessórios | P15: 45718 | Q15: 112.32 | R15: Itaú
B16: 20/10 | C16: Outros | D16: 325 | E16: Nubank | G16: 45943 | H16: Canva Mãe | I16: Reembolsos | J16: 34.9 | K16: Nubank | M16: 45905 | N16: Compra centro | O16: Futilidades | P16: 45690 | Q16: 57 | R16: Itaú
B17: 24/10 | C17: Reembolsos | D17: 35 | E17: Itaú | G17: 45944 | H17: Gympass | I17: Bem-estar/Saúde | J17: 139.9 | K17: Itaú | M17: 45916 | N17: Presente Rafa | O17: Presentes | P17: 45690 | Q17: 87.95 | R17: Itaú
B18: 28/10 | C18: Rendimentos | D18: 23.78 | E18: Itaú | G18: 45946 | H18: Gympass André | I18: Reembolsos | J18: 189.9 | K18: Itaú | M18: 45919 | N18: DiSavoia pizzaria | O18: Eventos | P18: - | Q18: 80.21 | R18: Itaú
B19: 27/10 | C19: Aval | D19: 800 | E19: Itaú | G19: 45948 | H19: Google One | I19: Celular/tecnologia | J19: 14.99 | K19: Itaú | M19: 45920 | N19: Uber (aniver Mãe) | O19: Transporte | P19: - | Q19: 30.94 | R19: Itaú
C20: Total | D20: =SUM(D9:D19) -> 7343.51 | H20: Total | J20: =SUM(J9:J19) -> 1051.75 | M20: 45920 | N20: Uber (aniver Davi) | O20: Transporte | P20: - | Q20: 12.93 | R20: Itaú
C21: Salário mês | D21: 6627.11 | E21: =D21/D20 -> 0.90244447 | M21: 45921 | N21: 99 (aniver Davi) | O21: Transporte | P21: - | Q21: 31.5 | R21: Itaú
M22: 45921 | N22: 99moto (Velocity) | O22: Transporte | P22: - | Q22: 6.7 | R22: Itaú
M23: 45921 | N23: Principia | O23: Bem-estar/Saúde | P23: 45689 | Q23: 56.5 | R23: Itaú
M24: 45922 | N24: Livro Amazon | O24: Lazer | P24: - | Q24: 15.96 | R24: Itaú
C25: BALANÇO DO MÊS | M25: 45923 | N25: Corte cabelo | O25: Beleza | P25: - | Q25: 160 | R25: Itaú
D26: Valores | E26: Meta | M26: 45923 | N26: Lanche padaria | O26: Alimentação | P26: - | Q26: 13.34 | R26: Itaú
C27: Saldo inicial | D27: 16912.04 | M27: 45923 | N27: Morangos | O27: Alimentação | P27: - | Q27: 11.97 | R27: Itaú
C28: Entradas | D28: =D20 -> 7343.51 | M28: 45924 | N28: Araújo | O28: Bem-estar/Saúde | P28: - | Q28: 77.58 | R28: Itaú
C29: Fatura Itaú | D29: =SUMIF(R9:R97,"Itaú",Q9:Q97) + SUMIF(K9:K97,"Itaú",J9:J97) -> 4842.27 | E29: 4861.28 | M29: 45925 | N29: Chocolate Asmel | O29: Alimentação | P29: - | Q29: 4 | R29: Itaú
C30: Fatura NuBank | M30: 45926 | N30: Riachuelo | O30: Roupas/acessórios | P30: 45717 | Q30: 106.66 | R30: Itaú
C31: Saídas | D31: =SUM(J20,Q98) -> 5968.24 | M31: 45926 | N31: Presente Mãe | O31: Presentes | P31: 45689 | Q31: 51.75 | R31: Itaú
C32: Investidos | D32: =V13 -> 15200 | M32: 45926 | N32: Deck Boi na Brasa | O32: Eventos | P32: - | Q32: 43.15 | R32: Itaú
C33: Saldo do mês | D33: =SUM(D27,D28)- SUM(D31,D32) -> 3087.31 | M33: 45926 | N33: Banheiro Cidade | O33: Futilidades | P33: - | Q33: 2.5 | R33: Itaú
M34: 45927 | N34: Uber (niver Brandão) | O34: Transporte | P34: - | Q34: 10.92 | R34: Itaú
M35: 45928 | N35: Uber (arena do espeto) | O35: Transporte | P35: - | Q35: 25.91 | R35: Itaú
M36: 45928 | N36: 99 (arena do espeto) | O36: Transporte | P36: - | Q36: 23.8 | R36: Itaú
M37: 45928 | N37: Bebidas Arena do Espeto | O37: Eventos | P37: - | Q37: 46 | R37: Itaú
M38: 45931 | N38: Almoço Salubritá | O38: Alimentação | P38: - | Q38: 25.05 | R38: Itaú
M39: 45931 | N39: Uber inloco | O39: Reembolsos | P39: - | Q39: 84.96 | R39: Itaú
M40: 45931 | N40: Uber inloco | O40: Reembolsos | P40: - | Q40: 101.6 | R40: Itaú
M41: 45932 | N41: Marcação laser | O41: Beleza | P41: - | Q41: 20 | R41: Pix
M42: 45932 | N42: Uber Asmel | O42: Transporte | P42: - | Q42: 24.96 | R42: Itaú
M43: 45932 | N43: Lanche Asmel | O43: Alimentação | P43: - | Q43: 11 | R43: Itaú
M44: 45933 | N44: Picolé Oggi | O44: Alimentação | P44: - | Q44: 2.75 | R44: Itaú
M45: 45933 | N45: Lojas Rede | O45: Bem-estar/Saúde | P45: - | Q45: 23.99 | R45: Itaú
...

Sheet Novembro
G2: Novembro
B7: ENTRADAS | G7: GASTOS FIXOS | M7: GASTOS VARIÁVEIS | T7: COFRINHOS
B8: Data | C8: Descrição | D8: Valor | E8: Forma | G8: Data | H8: Descrição | I8: Categoria | J8: Valor | K8: Forma | M8: Data | N8: Descrição | O8: Categoria | P8: Parcelas | Q8: Valor | R8: Forma | T8: Data | U8: Categoria | V8: Valor | W8: Rendimentos | X8: Prazo | Y8: Progreso | Z8: Meta
B9: 12/11 | C9: Salubritá | D9: 3527.91 | E9: Itaú | G9: 45949 | H9: WeMeds | I9: Educação médica | J9: 34.99 | K9: Itaú | M9: 45751 | N9: Tênis André | O9: Reembolsos | P9: 8/9 | Q9: 99.99 | R9: Nubank | T9: 45984 | U9: Reserva | V9: 400 | X9: - | Y9: =(V9:V98/Z9:Z98) -> 0.016 | Z9: 25000
B10: 13/11 | C10: Asmel | D10: 2184 | E10: Itaú | G10: 45955 | H10: Ta de Clinicagem | I10: Educação médica | J10: 44.9 | K10: Itaú | M10: 45891 | N10: Autoescola | O10: Educação médica | P10: 3/3 | Q10: 390.22 | R10: Itaú | T10: 45984 | U10: Móveis | V10: 500 | X10: 46447 | Y10: =(V9:V98/Z9:Z98) -> 0.01 | Z10: 50000
B11: 12/11 | C11: Aval | D11: 1500 | E11: Itaú | G11: 45956 | H11: Vivo Celular | I11: Celular/tecnologia | J11: 85 | K11: Itaú | M11: 45905 | N11: Tênis Andrê | O11: Reembolsos | P11: 3/9 | Q11: 100.07 | R11: Itaú | T11: 45984 | U11: Residência | V11: 2800 | X11: 46023 | Y11: =(V9:V98/Z9:Z98) -> 0.43076923 | Z11: 6500
B12: 26/11 | C12: Aval | D12: 1766.66 | E12: Itaú | G12: 45964 | H12: Contabilidade | I12: Contabilidade/impostos | J12: 282.4 | K12: Boleto | M12: 45905 | N12: Marisa | O12: Roupas/acessórios | P12: 3/3 | Q12: 113.32 | R12: Itaú | T12: 45984 | U12: Viagem | V12: 550 | X12: 45992 | Y12: =(V9:V98/Z9:Z98) -> 0.11 | Z12: 5000
B13: 05/11 | C13: Reembolsos | D13: 300 | E13: Nubank | G13: 45965 | H13: Spotify | I13: Lazer | J13: 15.95 | K13: Pix | M13: 45921 | N13: Principia | O13: Bem-estar/Saúde | P13: 2/2 | Q13: 56.5 | R13: Itaú | U13: Total | V13: =SUM(V9:V12) -> 4250 | Y13: =(V9:V98/Z9:Z98) -> 0.049132948 | Z13: =SUM(Z9:Z12) -> 86500
B14: 18/11 | C14: Rendimentos | D14: 2.69 | E14: Itaú | G14: 45966 | H14: Imposto de Renda PJ | I14: Contabilidade/impostos | J14: 98.53 | K14: Boleto | M14: 45926 | N14: Riachuelo | O14: Roupas/acessórios | P14: 2/3 | Q14: 106.66 | R14: Itaú
B15: 18/11 | C15: Reembolsos | D15: 23.78 | E15: Itaú | G15: 45972 | H15: Canva Mãe | I15: Reembolsos | J15: 34.9 | K15: Nubank | M15: 45926 | N15: Presente Mãe | O15: Presentes | P15: 2/2 | Q15: 51.75 | R15: Itaú
G16: 45973 | H16: Manicure | I16: Beleza | J16: 144.44 | K16: Itaú | M16: 45933 | N16: Vestido amarelo | O16: Roupas/acessórios | P16: 2/2 | Q16: 100 | R16: Itaú
G17: 45973 | H17: Whitebook | I17: Educação médica | J17: 69.9 | K17: Itaú | M17: 45937 | N17: Beco acessórios | O17: Roupas/acessórios | P17: 2/2 | Q17: 40.5 | R17: Itaú
G18: 45975 | H18: Gympass | I18: Bem-estar/Saúde | J18: 139.9 | K18: Itaú | M18: 45937 | N18: Acessórios Chinês | O18: Roupas/acessórios | P18: 2/2 | Q18: 66 | R18: Itaú
G19: 45979 | H19: Google One | I19: Celular/tecnologia | J19: 14.99 | K19: Itaú | M19: 45938 | N19: Natura | O19: Beleza | P19: 2/2 | Q19: 62.4 | R19: Itaú
C20: Total | D20: =SUM(D9:D19) -> 9305.04 | G20: 45975 | H20: Imposto PJ (DAS) | I20: Contabilidade/impostos | J20: 191.95 | K20: Boleto | M20: 45940 | N20: Headphone | O20: Lazer | P20: 2/2 | Q20: 75 | R20: Itaú
C21: Salário mês | D21: 8978.57 | E21: =D21/D20 -> 0.96491471 | H21: Total | J21: =SUM(J9:J20) -> 1157.85 | M21: 45946 | N21: Avião Bahia | O21: Viagens | P21: 1/9 | Q21: 99.82 | R21: Itaú
M22: 45948 | N22: Xeque mate | O22: Eventos | P22: - | Q22: 20 | R22: Itaú
M23: 45949 | N23: Bar do Orlando | O23: Eventos | P23: - | Q23: 56.1 | R23: Itaú
M24: 45949 | N24: Araújo lanche Enare | O24: Alimentação | P24: - | Q24: 25.65 | R24: Itaú
M25: 45949 | N25: 99 volta casa | O25: Transporte | P25: - | Q25: 26.95 | R25: Itaú
M26: 45949 | N26: 99 Enare | O26: Transporte | P26: - | Q26: 22.05 | R26: Itaú
H27: BALANÇO DO MÊS | M27: 45949 | N27: 99 Bar do Orlando | O27: Transporte | P27: - | Q27: 15.9 | R27: Itaú
I28: Valores | J28: Meta | M28: 45949 | N28: Barrigudinha 1000ton | O28: Eventos | P28: - | Q28: 12 | R28: Itaú
H29: Saldo inicial | I29: 3273.46 | M29: 45950 | N29: Acessórios Chinês | O29: Roupas/acessórios | P29: - | Q29: 30 | R29: Itaú
H30: Entradas | I30: =D20 -> 9305.04 | M30: 45951 | N30: Araújo shampoo | O30: Bem-estar/Saúde | P30: 45689 | Q30: 58.52 | R30: Itaú
H31: Fatura Itaú | I31: =SUMIF(R9:R98,"Itaú",Q9:Q98) + SUMIF(K9:K98,"Itaú",J9:J98) -> 4435.33 | M31: 45951 | N31: Ingresso Mira! | O31: Eventos | P31: - | Q31: 67.5 | R31: Itaú
H32: Fatura NuBank | M32: 45951 | N32: BhBus | O32: Transporte | P32: - | Q32: 50 | R32: Itaú
H33: Saídas | I33: =SUM(J21,Q95) -> 6698.61 | M33: 45952 | N33: Câmera digital Kodak | O33: Futilidades | P33: 45992 | Q33: 133.22 | R33: Itaú
H34: Investidos | I34: =V13 -> 4250 | M34: 45953 | N34: Uber Asmel | O34: Transporte | P34: - | Q34: 32.67 | R34: Itaú
H35: Saldo do mês | I35: =SUM(I29,I30)- SUM(I33,I34) -> 1629.89 | M35: 45953 | N35: Chicletes Asmel | O35: Alimentação | P35: - | Q35: 3.5 | R35: Itaú
M36: 45954 | N36: Deck Boi na Brasa | O36: Eventos | P36: - | Q36: 60 | R36: Itaú
M37: 45954 | N37: Uber Tuanny | O37: Transporte | P37: - | Q37: 17.93 | R37: Itaú
M38: 45955 | N38: 99 Dona Margherita | O38: Transporte | P38: - | Q38: 26.25 | R38: Itaú
M39: 45955 | N39: Bebidas Mira! | O39: Eventos | P39: - | Q39: 48 | R39: Itaú
M40: 45955 | N40: Bebidas Resenha da Naty | O40: Eventos | P40: - | Q40: 36 | R40: Itaú
M41: 45955 | N41: 99 Dona Margherita | O41: Transporte | P41: - | Q41: 19.3 | R41: Itaú
M42: 45955 | N42: Rodízio de Pizza | O42: Eventos | P42: - | Q42: 93.28 | R42: Itaú
M43: 45955 | N43: Uber Aniver Otati | O43: Transporte | P43: - | Q43: 17.96 | R43: Itaú
M44: 45956 | N44: Almoço Sagradinha | O44: Eventos | P44: - | Q44: 52 | R44: Itaú
M45: 45956 | N45: Sorvete Sagradinha | O45: Eventos | P45: - | Q45: 12.56 | R45: Itaú
...

Sheet Dezembro
G2: Dezembro
B7: ENTRADAS | G7: GASTOS FIXOS | M7: GASTOS VARIÁVEIS | T7: COFRINHOS
B8: Data | C8: Descrição | D8: Valor | E8: Forma | G8: Data | H8: Descrição | I8: Categoria | J8: Valor | K8: Forma | M8: Data | N8: Descrição | O8: Categoria | P8: Parcelas | Q8: Valor | R8: Forma | T8: Data | U8: Categoria | V8: Valor | W8: Rendimentos | X8: Prazo | Y8: Progreso | Z8: Meta
B9: 10/12 | C9: Aval | D9: 1486.66 | G9: 45980 | H9: WeMeds | I9: Educação médica | J9: 34.99 | K9: Itaú | M9: 45751 | N9: Tênis André | O9: Presentes | P9: 9/9 | Q9: 99.99 | R9: Nubank
C10: Salubritá | D10: 3410 | G10: 45986 | H10: Ta de Clinicagem | I10: Educação médica | J10: 44.9 | K10: Itaú | M10: 45905 | N10: Tênis Andrê | O10: Reembolsos | P10: 4/9 | Q10: 100.07 | R10: Itaú
C11: Aval | D11: 1840 | G11: 45987 | H11: Vivo Celular | I11: Celular/tecnologia | J11: 100 | K11: Itaú | M11: 45926 | N11: Riachuelo | O11: Roupas/acessórios | P11: 3/3 | Q11: 106.66 | R11: Itaú
C12: Asmel | D12: 2240 | H12: Contabilidade | I12: Contabilidade/impostos | J12: 282.4 | K12: Boleto | M12: 45926 | N12: Riachuelo | O12: Roupas/acessórios | P12: 3/3 | Q12: 106.66 | R12: Itaú
G13: 45995 | H13: Spotify | I13: Lazer | J13: 15.95 | K13: Pix | M13: 45946 | N13: Avião Bahia | O13: Viagens | P13: 2/9 | Q13: 99.82 | R13: Itaú
H14: Imposto de Renda PJ | I14: Contabilidade/impostos | K14: Boleto | M14: 45952 | N14: Câmera digital Kodak | O14: Futilidades | P14: 2/12 | Q14: 133.22 | R14: Itaú
G15: 46002 | H15: Canva Mãe | I15: Reembolsos | J15: 34.9 | K15: Nubank | M15: 45952 | N15: Araújo shampoo | O15: Bem-estar/Saúde | P15: 2/2 | Q15: 58.52 | R15: Itaú
G16: 46008 | H16: Manicure | I16: Beleza | J16: 148.92 | K16: Itaú | M16: 45971 | N16: Shein ano novo | O16: Roupas/acessórios | P16: 2/3 | Q16: 77.93 | R16: Itaú
G17: 46003 | H17: Whitebook | I17: Educação médica | J17: 69.9 | K17: Itaú | M17: 45972 | N17: Shein praia | O17: Roupas/acessórios | P17: 2/3 | Q17: 151.09 | R17: Itaú
G18: 46005 | H18: Gympass | I18: Bem-estar/Saúde | J18: 139.9 | K18: Itaú | M18: 45978 | N18: Araújo curativos | O18: Bem-estar/Saúde | P18: 2/2 | Q18: 118.41 | R18: Itaú
G19: 46009 | H19: Google One | I19: Celular/tecnologia | J19: 14.99 | K19: Itaú | M19: 45980 | N19: 99 Aval | O19: Transporte | P19: - | Q19: 9.9 | R19: Itaú
C20: Total | D20: =SUM(D9:D19) -> 8976.66 | G20: 45994 | H20: Imposto de Renda PJ | I20: Contabilidade/impostos | J20: 108.65 | K20: Boleto | M20: 45980 | N20: Almoço Aval | O20: Alimentação | P20: - | Q20: 32.98 | R20: Itaú
C21: Salário mês | E21: =D21/D20 -> 0 | M21: 45981 | N21: 99 vó | O21: Transporte | P21: - | Q21: 12.2 | R21: Itaú
M22: 45981 | N22: Cerveja 1000ton | O22: Eventos | P22: - | Q22: 73.25 | R22: Itaú
M23: 45981 | N23: Uber 1000ton | O23: Transporte | P23: - | Q23: 25.96 | R23: Itaú
M24: 45982 | N24: Uber 1000ton | O24: Transporte | P24: - | Q24: 41.99 | R24: Itaú
M25: 45982 | N25: Pao de queijo Aval | O25: Alimentação | P25: - | Q25: 8 | R25: Itaú
M26: 45982 | N26: 99 churras Isadora | O26: Transporte | P26: - | Q26: 13.8 | R26: Itaú
M27: 45982 | N27: Champanhe Isadora | O27: Presentes | P27: - | Q27: 55 | R27: Itaú
M28: 45982 | N28: 99 casa Isadora | O28: Transporte | P28: - | Q28: 26.8 | R28: Itaú
M29: 45982 | N29: 99 Porks | O29: Transporte | P29: - | Q29: 18.15 | R29: Itaú
M30: 45984 | N30: Araújo | O30: Bem-estar/Saúde | P30: - | Q30: 25.28 | R30: Itaú
M31: 45985 | N31: Americanas doces | O31: Futilidades | P31: - | Q31: 35.97 | R31: Itaú
M32: 45985 | N32: 99 Aval | O32: Transporte | P32: - | Q32: 19.6 | R32: Itaú
M33: 45985 | N33: Dentista | O33: Bem-estar/Saúde | P33: 45689 | Q33: 75 | R33: Itaú
M34: 45985 | N34: Dentista André | O34: Reembolsos | P34: 45689 | Q34: 75 | R34: Itaú
M35: 45985 | N35: Medway | O35: Educação médica | P35: 45992 | Q35: 1035.39 | R35: Itaú
M36: 45986 | N36: Almoço Salubritá | O36: Alimentação | P36: - | Q36: 40.55 | R36: Itaú
M37: 45986 | N37: Shampoo Ápice | O37: Beleza | P37: - | Q37: 67.73 | R37: Itaú
M38: 45986 | N38: 99 Unimed Vó | O38: Transporte | P38: - | Q38: 13.3 | R38: Itaú
M39: 45986 | N39: 99 Casa Vó | O39: Transporte | P39: - | Q39: 32.2 | R39: Itaú
M40: 45986 | N40: Clareamento André | O40: Reembolsos | P40: 45992 | Q40: 91.74 | R40: Itaú
M41: 45987 | N41: 99 Salubritá | O41: Transporte | P41: - | Q41: 22.2 | R41: Itaú
M42: 45988 | N42: Chicletes Asmel | O42: Alimentação | P42: - | Q42: 3.5 | R42: Itaú
M43: 45988 | N43: 99 Asmel | O43: Transporte | P43: - | Q43: 21.95 | R43: Itaú
M44: 45989 | N44: Cama box | O44: Casa | P44: 45992 | Q44: 286.49 | R44: Itaú
C45: BALANÇO DO MÊS | M45: 45989 | N45: Lente de contato | O45: Bem-estar/Saúde | P45: 45717 | Q45: 90.92 | R45: Itaú
...

Sheet Cópia de Dezembro
G2: Dezembro
B7: ENTRADAS | G7: GASTOS FIXOS | M7: GASTOS VARIÁVEIS | T7: COFRINHOS
B8: Data | C8: Descrição | D8: Valor | E8: Forma | G8: Data | H8: Descrição | I8: Categoria | J8: Valor | K8: Forma | M8: Data | N8: Descrição | O8: Categoria | P8: Parcelas | Q8: Valor | R8: Forma | T8: Data | U8: Categoria | V8: Valor | W8: Rendimentos | X8: Prazo | Y8: Progreso | Z8: Meta
B9: 10/12 | C9: Aval | D9: 1486.66 | G9: 45980 | H9: WeMeds | I9: Educação médica | J9: 34.99 | K9: Itaú | M9: 45751 | N9: Tênis André | O9: Presentes | P9: 9/9 | Q9: 99.99 | R9: Nubank
C10: Salubritá | D10: 3410 | G10: 45986 | H10: Ta de Clinicagem | I10: Educação médica | J10: 44.9 | K10: Itaú | M10: 45905 | N10: Tênis Andrê | O10: Reembolsos | P10: 4/9 | Q10: 100.07 | R10: Itaú
C11: Aval | D11: 1840 | G11: 45987 | H11: Vivo Celular | I11: Celular/tecnologia | J11: 100 | K11: Itaú | M11: 45926 | N11: Riachuelo | O11: Roupas/acessórios | P11: 3/3 | Q11: 106.66 | R11: Itaú
C12: Asmel | D12: 2240 | H12: Contabilidade | I12: Contabilidade/impostos | J12: 282.4 | K12: Boleto | M12: 45926 | N12: Riachuelo | O12: Roupas/acessórios | P12: 3/3 | Q12: 106.66 | R12: Itaú
G13: 45995 | H13: Spotify | I13: Lazer | J13: 15.95 | K13: Pix | M13: 45946 | N13: Avião Bahia | O13: Viagens | P13: 2/9 | Q13: 99.82 | R13: Itaú
H14: Imposto de Renda PJ | I14: Contabilidade/impostos | K14: Boleto | M14: 45952 | N14: Câmera digital Kodak | O14: Futilidades | P14: 2/12 | Q14: 133.22 | R14: Itaú
G15: 46002 | H15: Canva Mãe | I15: Reembolsos | J15: 34.9 | K15: Nubank | M15: 45952 | N15: Araújo shampoo | O15: Bem-estar/Saúde | P15: 2/2 | Q15: 58.52 | R15: Itaú
G16: 46008 | H16: Manicure | I16: Beleza | J16: 148.92 | K16: Itaú | M16: 45971 | N16: Shein ano novo | O16: Roupas/acessórios | P16: 2/3 | Q16: 77.93 | R16: Itaú
G17: 46003 | H17: Whitebook | I17: Educação médica | J17: 69.9 | K17: Itaú | M17: 45972 | N17: Shein praia | O17: Roupas/acessórios | P17: 2/3 | Q17: 151.09 | R17: Itaú
G18: 46005 | H18: Gympass | I18: Bem-estar/Saúde | J18: 139.9 | K18: Itaú | M18: 45978 | N18: Araújo curativos | O18: Bem-estar/Saúde | P18: 2/2 | Q18: 118.41 | R18: Itaú
G19: 46009 | H19: Google One | I19: Celular/tecnologia | J19: 14.99 | K19: Itaú | M19: 45980 | N19: 99 Aval | O19: Transporte | P19: - | Q19: 9.9 | R19: Itaú
C20: Total | D20: =SUM(D9:D19) -> 8976.66 | G20: 45994 | H20: Imposto de Renda PJ | I20: Contabilidade/impostos | J20: 108.65 | K20: Boleto | M20: 45980 | N20: Almoço Aval | O20: Alimentação | P20: - | Q20: 32.98 | R20: Itaú
C21: Salário mês | E21: =D21/D20 -> 0 | M21: 45981 | N21: 99 vó | O21: Transporte | P21: - | Q21: 12.2 | R21: Itaú
M22: 45981 | N22: Cerveja 1000ton | O22: Eventos | P22: - | Q22: 73.25 | R22: Itaú
M23: 45981 | N23: Uber 1000ton | O23: Transporte | P23: - | Q23: 25.96 | R23: Itaú
M24: 45982 | N24: Uber 1000ton | O24: Transporte | P24: - | Q24: 41.99 | R24: Itaú
M25: 45982 | N25: Pao de queijo Aval | O25: Alimentação | P25: - | Q25: 8 | R25: Itaú
M26: 45982 | N26: 99 churras Isadora | O26: Transporte | P26: - | Q26: 13.8 | R26: Itaú
M27: 45982 | N27: Champanhe Isadora | O27: Presentes | P27: - | Q27: 55 | R27: Itaú
M28: 45982 | N28: 99 casa Isadora | O28: Transporte | P28: - | Q28: 26.8 | R28: Itaú
M29: 45982 | N29: 99 Porks | O29: Transporte | P29: - | Q29: 18.15 | R29: Itaú
M30: 45984 | N30: Araújo | O30: Bem-estar/Saúde | P30: - | Q30: 25.28 | R30: Itaú
M31: 45985 | N31: Americanas doces | O31: Futilidades | P31: - | Q31: 35.97 | R31: Itaú
M32: 45985 | N32: 99 Aval | O32: Transporte | P32: - | Q32: 19.6 | R32: Itaú
M33: 45985 | N33: Dentista | O33: Bem-estar/Saúde | P33: 45689 | Q33: 75 | R33: Itaú
M34: 45985 | N34: Dentista André | O34: Reembolsos | P34: 45689 | Q34: 75 | R34: Itaú
M35: 45985 | N35: Medway | O35: Educação médica | P35: 45992 | Q35: 1035.39 | R35: Itaú
M36: 45986 | N36: Almoço Salubritá | O36: Alimentação | P36: - | Q36: 40.55 | R36: Itaú
M37: 45986 | N37: Shampoo Ápice | O37: Beleza | P37: - | Q37: 67.73 | R37: Itaú
M38: 45986 | N38: 99 Unimed Vó | O38: Transporte | P38: - | Q38: 13.3 | R38: Itaú
M39: 45986 | N39: 99 Casa Vó | O39: Transporte | P39: - | Q39: 32.2 | R39: Itaú
M40: 45986 | N40: Clareamento André | O40: Reembolsos | P40: 45992 | Q40: 91.74 | R40: Itaú
M41: 45987 | N41: 99 Salubritá | O41: Transporte | P41: - | Q41: 22.2 | R41: Itaú
M42: 45988 | N42: Chicletes Asmel | O42: Alimentação | P42: - | Q42: 3.5 | R42: Itaú
M43: 45988 | N43: 99 Asmel | O43: Transporte | P43: - | Q43: 21.95 | R43: Itaú
M44: 45989 | N44: Cama box | O44: Casa | P44: 45992 | Q44: 286.49 | R44: Itaú
C45: BALANÇO DO MÊS | M45: 45989 | N45: Lente de contato | O45: Bem-estar/Saúde | P45: 45717 | Q45: 90.92 | R45: Itaú
...

Sheet Painel Geral
A1: m
L4: OUT | M4: NOV | N4: DEZ
K5: ENTRADAS | L5: =Outubro!D28 -> 7343.51 | M5: =Novembro!I30 -> 9305.04 | N5: =Dezembro!D48 -> 8976.66
K6: SAÍDAS | L6: =Outubro!D31 -> 5968.24 | M6: =Novembro!I33 -> 6698.61 | N6: =Dezembro!D51 -> 5196.89
K7: INVESTIDO | L7: =Outubro!D32 -> 15200 | M7: =Novembro!I34 -> 4250 | N7: =Dezembro!D52 -> 0
K8: SALDO | L8: =Outubro!D33 -> 3087.31 | M8: =Novembro!I35 -> 1629.89 | N8: =Dezembro!D53 -> 3779.77
L10: SALÁRIO MIN | M10: 6880
L11: GASTOS MÁX | M11: 3440
L12: INVEST MIN | M12: 3440

Sheet Whish list
E7: Whish List 2025
F8: Valor | G8: Prioridade | H8: Prazo | I8: Data | J8: Comprado
E9: Mala de viagem | G9: Baixa | H9: - | I9: - | J9: FALSE
E10: Silicone | F10: 30000 | G10: Média | H10: - | I10: - | J10: FALSE
E11: Calcinhas | G11: Alta | H11: - | I11: - | J11: FALSE
E12: Roupas de trabalhar | F12: 300 | G12: Alta | H12: - | I12: - | J12: FALSE
E13: Roupas de academia | F13: 700 | G13: Média | H13: - | I13: - | J13: FALSE
E14: Cadeira escritório | F14: 600 | G14: Alta | H14: - | I14: - | J14: FALSE
E15: TV | F15: 2000 | G15: Baixa | H15: - | I15: - | J15: FALSE
E16: Bota meia pata | F16: 250 | G16: Baixa | H16: - | I16: - | J16: FALSE
E17: Regatas Miso | F17: 150 | G17: Baixa | H17: - | I17: - | J17: FALSE
E18: Cartão de memória | F18: 45 | G18: Média | H18: 46020 | I18: - | J18: TRUE
E19: Cursinho R1 | F19: 12000 | G19: Alta | J19: TRUE
E20: Cama Box | F20: 4200 | G20: Média | H20: - | I20: - | J20: TRUE
E21: Escrivaninha | F21: 1000 | G21: Alta | H21: - | I21: - | J21: TRUE
E22: Roupas Shein | F22: 900 | G22: Média | H22: 46020 | I22: - | J22: TRUE
E23: Camera digital | F23: 1598.64 | G23: Baixa | H23: 46020 | I23: 45952 | J23: TRUE
E24: Total | F24: =SUM(F9:F22) -> 52145

Sheet Cofrinhos
F2: Cofrinhos
K3: GUARDADO | L3: =SUM(E15,E31,E47,E64,E82) -> 19685.75
K4: META | L4: =SUM(E16,E32,E48,E65,E83) -> 116500
K5: PROGRESSO | L5: =L3/L4 -> 0.16897639
E8: OUT | F8: NOV | G8: DEZ | H8: JAN | I8: FEV | J8: MAR | K8: ABR | L8: MAIO | M8: JUN | N8: JUL | O8: AGOS | P8: SET
C9: RESIDÊNCIA | D9: ENTRADAS | E9: 3200 | F9: 2800
D10: SAÍDAS | E10: - | F10: -
D11: RENDIMENTOS | F11: 52.56
D12: META MENSAL | E12: 3000 | F12: 3000 | G12: 3000 | H12: 3000 | I12: 3000 | J12: 3000 | K12: 3000 | L12: 3000 | M12: 3000 | N12: 3000 | O12: 3000 | P12: 3000
E13: TRUE | F13: TRUE | G13: FALSE | H13: FALSE | I13: FALSE | J13: FALSE | K13: FALSE | L13: FALSE | M13: FALSE | N13: FALSE | O13: FALSE | P13: FALSE
D14: BALANÇO | E14: =200 -> 200 | F14: 52.56
D15: TOTAL | E15: =SUM(E9:P9,E11:P11)-SUM(E10:P10) -> 6052.56 | O15: PRAZO | P15: MAR/2027
D16: META TOTAL | E16: 50000 | O16: TEMPO TOTAL | P16: 17 MESES
D17: PROGRESSO | E17: =E15/E16 -> 0.1210512
E24: OUT | F24: NOV | G24: DEZ | H24: JAN | I24: FEV | J24: MAR | K24: ABR | L24: MAIO | M24: JUN | N24: JUL | O24: AGOS | P24: SET
C25: RESERVA | D25: ENTRADAS | E25: 10000 | F25: 400
D26: SAÍDAS | E26: - | F26: -
D27: RENDIMENTOS | F27: 151.76
D28: META MENSAL
E29: TRUE | F29: TRUE | G29: FALSE | H29: FALSE | I29: FALSE | J29: FALSE | K29: FALSE | L29: FALSE | M29: FALSE | N29: FALSE | O29: FALSE | P29: FALSE
D30: BALANÇO
D31: TOTAL | E31: =SUM(E25:P25,E27:P27)-SUM(E26:P26) -> 10551.76 | O31: PRAZO | P31: -
D32: META TOTAL | E32: 25000 | O32: TEMPO TOTAL | P32: -
D33: PROGRESSO | E33: =E31/E32 -> 0.4220704
E40: OUT | F40: NOV | G40: DEZ | H40: JAN | I40: FEV | J40: MAR | K40: ABR | L40: MAIO | M40: JUN | N40: JUL | O40: AGOS | P40: SET
C41: MÓVEIS | D41: ENTRADAS | E41: 1000 | F41: 500
D42: SAÍDAS | E42: -
D43: RENDIMENTOS | F43: 15.67
D44: META MENSAL | E44: 1625 | F44: 1625 | G44: 1625 | H44: 1625
E45: FALSE | F45: FALSE | G45: FALSE | H45: FALSE | I45: FALSE | J45: FALSE | K45: FALSE | L45: FALSE | M45: FALSE | N45: FALSE | O45: FALSE | P45: FALSE
D46: BALANÇO
D47: TOTAL | E47: =SUM(E41:P41,E43:P43)-SUM(E42:P42) -> 1515.67 | O47: PRAZO | P47: 01/2026
D48: META TOTAL | E48: 6500 | O48: TEMPO TOTAL | P48: 4 MESES
D49: PROGRESSO | E49: =E47/E48 -> 0.23318
E57: OUT | F57: NOV | G57: DEZ | H57: JAN | I57: FEV | J57: MAR | K57: ABR | L57: MAIO | M57: JUN | N57: JUL | O57: AGOS | P57: SET
C58: BAHIA | D58: ENTRADAS | E58: 1000 | F58: 550
D59: SAÍDAS | E59: -
D60: RENDIMENTOS | F60: 15.76
D61: META MENSAL | E61: 1700 | F61: 1700 | G61: 1700
E62: FALSE | F62: FALSE | G62: FALSE | H62: FALSE | I62: FALSE | J62: FALSE | K62: FALSE | L62: FALSE | M62: FALSE | N62: FALSE | O62: FALSE | P62: FALSE
...
